2025-05-26 10:44:23,305 - RealtimeQuoteCollector - INFO - 采集到 5720 条股票行情数据
2025-05-26 10:44:24,158 - RealtimeQuoteCollector - INFO - 全部股票行情数据采集并入库完成
2025-05-26 10:50:57,544 - RealtimeQuoteCollector - INFO - 采集到 5720 条股票行情数据
2025-05-26 10:50:58,346 - RealtimeQuoteCollector - INFO - 全部股票行情数据采集并入库完成
2025-05-27 16:33:28,510 - RealtimeQuoteCollector - INFO - 采集到 5720 条股票行情数据
2025-05-27 16:33:29,446 - RealtimeQuoteCollector - INFO - 全部股票行情数据采集并入库完成
2025-05-31 10:42:18,040 - RealtimeQuoteCollector - WARNING - 第 1 次重试失败: ('Connection aborted.', RemoteDisconnected('Remote end closed connection without response'))
2025-05-31 10:42:23,142 - RealtimeQuoteCollector - WARNING - 第 2 次重试失败: ('Connection aborted.', RemoteDisconnected('Remote end closed connection without response'))
2025-05-31 10:42:28,273 - RealtimeQuoteCollector - ERROR - 函数 stock_zh_a_spot_em 执行失败: ('Connection aborted.', RemoteDisconnected('Remote end closed connection without response'))
2025-05-31 10:42:28,274 - RealtimeQuoteCollector - ERROR - 采集或入库时出错: ('Connection aborted.', RemoteDisconnected('Remote end closed connection without response'))
Traceback (most recent call last):
  File "C:\Users\Admin\AppData\Local\Programs\Python\Python312\Lib\site-packages\urllib3\connectionpool.py", line 787, in urlopen
    response = self._make_request(
               ^^^^^^^^^^^^^^^^^^^
  File "C:\Users\Admin\AppData\Local\Programs\Python\Python312\Lib\site-packages\urllib3\connectionpool.py", line 534, in _make_request
    response = conn.getresponse()
               ^^^^^^^^^^^^^^^^^^
  File "C:\Users\Admin\AppData\Local\Programs\Python\Python312\Lib\site-packages\urllib3\connection.py", line 516, in getresponse
    httplib_response = super().getresponse()
                       ^^^^^^^^^^^^^^^^^^^^^
  File "C:\Users\Admin\AppData\Local\Programs\Python\Python312\Lib\http\client.py", line 1428, in getresponse
    response.begin()
  File "C:\Users\Admin\AppData\Local\Programs\Python\Python312\Lib\http\client.py", line 331, in begin
    version, status, reason = self._read_status()
                              ^^^^^^^^^^^^^^^^^^^
  File "C:\Users\Admin\AppData\Local\Programs\Python\Python312\Lib\http\client.py", line 300, in _read_status
    raise RemoteDisconnected("Remote end closed connection without"
http.client.RemoteDisconnected: Remote end closed connection without response

During handling of the above exception, another exception occurred:

Traceback (most recent call last):
  File "C:\Users\Admin\AppData\Local\Programs\Python\Python312\Lib\site-packages\requests\adapters.py", line 667, in send
    resp = conn.urlopen(
           ^^^^^^^^^^^^^
  File "C:\Users\Admin\AppData\Local\Programs\Python\Python312\Lib\site-packages\urllib3\connectionpool.py", line 841, in urlopen
    retries = retries.increment(
              ^^^^^^^^^^^^^^^^^^
  File "C:\Users\Admin\AppData\Local\Programs\Python\Python312\Lib\site-packages\urllib3\util\retry.py", line 474, in increment
    raise reraise(type(error), error, _stacktrace)
          ^^^^^^^^^^^^^^^^^^^^^^^^^^^^^^^^^^^^^^^^
  File "C:\Users\Admin\AppData\Local\Programs\Python\Python312\Lib\site-packages\urllib3\util\util.py", line 38, in reraise
    raise value.with_traceback(tb)
  File "C:\Users\Admin\AppData\Local\Programs\Python\Python312\Lib\site-packages\urllib3\connectionpool.py", line 787, in urlopen
    response = self._make_request(
               ^^^^^^^^^^^^^^^^^^^
  File "C:\Users\Admin\AppData\Local\Programs\Python\Python312\Lib\site-packages\urllib3\connectionpool.py", line 534, in _make_request
    response = conn.getresponse()
               ^^^^^^^^^^^^^^^^^^
  File "C:\Users\Admin\AppData\Local\Programs\Python\Python312\Lib\site-packages\urllib3\connection.py", line 516, in getresponse
    httplib_response = super().getresponse()
                       ^^^^^^^^^^^^^^^^^^^^^
  File "C:\Users\Admin\AppData\Local\Programs\Python\Python312\Lib\http\client.py", line 1428, in getresponse
    response.begin()
  File "C:\Users\Admin\AppData\Local\Programs\Python\Python312\Lib\http\client.py", line 331, in begin
    version, status, reason = self._read_status()
                              ^^^^^^^^^^^^^^^^^^^
  File "C:\Users\Admin\AppData\Local\Programs\Python\Python312\Lib\http\client.py", line 300, in _read_status
    raise RemoteDisconnected("Remote end closed connection without"
urllib3.exceptions.ProtocolError: ('Connection aborted.', RemoteDisconnected('Remote end closed connection without response'))

During handling of the above exception, another exception occurred:

Traceback (most recent call last):
  File "E:\wangxw\股票分析软件\编码\stock_quote_analayze\backend_core\data_collectors\akshare\realtime.py", line 101, in collect_quotes
    df = self._retry_on_failure(ak.stock_zh_a_spot_em)
         ^^^^^^^^^^^^^^^^^^^^^^^^^^^^^^^^^^^^^^^^^^^^^
  File "E:\wangxw\股票分析软件\编码\stock_quote_analayze\backend_core\data_collectors\akshare\base.py", line 74, in _retry_on_failure
    return func(*args, **kwargs)
           ^^^^^^^^^^^^^^^^^^^^^
  File "C:\Users\Admin\AppData\Local\Programs\Python\Python312\Lib\site-packages\akshare\stock_feature\stock_hist_em.py", line 36, in stock_zh_a_spot_em
    temp_df = fetch_paginated_data(url, params)
              ^^^^^^^^^^^^^^^^^^^^^^^^^^^^^^^^^
  File "C:\Users\Admin\AppData\Local\Programs\Python\Python312\Lib\site-packages\akshare\utils\func.py", line 32, in fetch_paginated_data
    r = requests.get(url, params=params, timeout=timeout)
        ^^^^^^^^^^^^^^^^^^^^^^^^^^^^^^^^^^^^^^^^^^^^^^^^^
  File "C:\Users\Admin\AppData\Local\Programs\Python\Python312\Lib\site-packages\requests\api.py", line 73, in get
    return request("get", url, params=params, **kwargs)
           ^^^^^^^^^^^^^^^^^^^^^^^^^^^^^^^^^^^^^^^^^^^^
  File "C:\Users\Admin\AppData\Local\Programs\Python\Python312\Lib\site-packages\requests\api.py", line 59, in request
    return session.request(method=method, url=url, **kwargs)
           ^^^^^^^^^^^^^^^^^^^^^^^^^^^^^^^^^^^^^^^^^^^^^^^^^
  File "C:\Users\Admin\AppData\Local\Programs\Python\Python312\Lib\site-packages\requests\sessions.py", line 589, in request
    resp = self.send(prep, **send_kwargs)
           ^^^^^^^^^^^^^^^^^^^^^^^^^^^^^^
  File "C:\Users\Admin\AppData\Local\Programs\Python\Python312\Lib\site-packages\requests\sessions.py", line 703, in send
    r = adapter.send(request, **kwargs)
        ^^^^^^^^^^^^^^^^^^^^^^^^^^^^^^^
  File "C:\Users\Admin\AppData\Local\Programs\Python\Python312\Lib\site-packages\requests\adapters.py", line 682, in send
    raise ConnectionError(err, request=request)
requests.exceptions.ConnectionError: ('Connection aborted.', RemoteDisconnected('Remote end closed connection without response'))
2025-05-31 10:42:28,289 - RealtimeQuoteCollector - ERROR - 记录错误日志失败: cannot access local variable 'cursor' where it is not associated with a value
